<?xml version="1.0" encoding="utf-8"?>
<!-- This URDF was automatically created by SolidWorks to URDF Exporter! Originally created by Stephen Brawner (brawner@gmail.com) 
     Commit Version:   Build Version: 1.5.7479.33669
     For more information, please see http://wiki.ros.org/sw_urdf_exporter -->
<robot
  name="spot_micro_urdf_v3_rotated_base">
    <material name="blue">
    <color rgba="0. 0.7 1 1"/>
  </material>
  <material name="black">
    <color rgba="0.1 0.1 0.1 1"/>
  </material>
  <material name="grey">
    <color rgba="0.3 0.3 0.3 1"/>
  </material>
  <link
    name="base_link">
    <inertial>
      <origin
        xyz="0.016622 -0.00072045 0.0004418"
        rpy="0 0 0" />
      <mass
        value="0.9248" />
      <inertia
        ixx="0.00099241"
        ixy="-7.2183E-06"
        ixz="5.2376E-06"
        iyy="0.0011738"
        iyz="-6.544E-06"
        izz="0.00063265" />
    </inertial>
    <visual>
      <origin
        xyz="0 0 0"
        rpy="0 0 0" />
      <geometry>
        <mesh
          filename="package://spot_micro_urdf_v3_rotated_base/meshes/base_link.STL" />
      </geometry>
      <material
        name="blue">
      </material>
    </visual>
    <collision>
      <origin
        xyz="0 0 0"
        rpy="0 0 0" />
      <geometry>
        <mesh
          filename="package://spot_micro_urdf_v3_rotated_base/meshes/base_link.STL" />
      </geometry>
    </collision>
  </link>
  <link
    name="FL_hip_link">
    <inertial>
      <origin
        xyz="-0.023049 -0.011251 0.0030217"
        rpy="0 0 0" />
      <mass
        value="0.10229" />
      <inertia
        ixx="2.3388E-05"
        ixy="-3.7973E-08"
        ixz="-4.5621E-13"
        iyy="1.6266E-05"
        iyz="-3.6502E-07"
        izz="2.8445E-05" />
    </inertial>
    <visual>
      <origin
        xyz="0 0 0"
        rpy="0 0 0" />
      <geometry>
        <mesh
          filename="package://spot_micro_urdf_v3_rotated_base/meshes/FL_hip_link.STL" />
      </geometry>
      <material
        name="grey">
      </material>
    </visual>
    <collision>
      <origin
        xyz="0 0 0"
        rpy="0 0 0" />
      <geometry>
        <mesh
          filename="package://spot_micro_urdf_v3_rotated_base/meshes/FL_hip_link.STL" />
      </geometry>
    </collision>
  </link>
  <joint
    name="FL_hip_joint"
    type="revolute">
    <origin
      xyz="0.0766 0.039001 0.010875"
      rpy="1.5708 0 -3.1416" />
    <parent
      link="base_link" />
    <child
      link="FL_hip_link" />
    <axis
      xyz="-1 0 0" />
    <limit
      lower="-0.1745"
      upper="1.5708"
      effort="3"
      velocity="8" />
  </joint>
  <link
    name="FL_thigh_link">
    <inertial>
      <origin
        xyz="-0.0061957 -0.058673 0.023449"
        rpy="0 0 0" />
      <mass
        value="0.20833" />
      <inertia
        ixx="6.5328E-05"
        ixy="-2.5965E-06"
        ixz="7.6159E-09"
        iyy="4.1013E-05"
        iyz="7.2121E-08"
        izz="5.5965E-05" />
    </inertial>
    <visual>
      <origin
        xyz="0 0 0"
        rpy="0 0 0" />
      <geometry>
        <mesh
          filename="package://spot_micro_urdf_v3_rotated_base/meshes/FL_thigh_link.STL" />
      </geometry>
      <material
        name="blue">
      </material>
    </visual>
    <collision>
      <origin
        xyz="0 0 0"
        rpy="0 0 0" />
      <geometry>
        <mesh
          filename="package://spot_micro_urdf_v3_rotated_base/meshes/FL_thigh_link.STL" />
      </geometry>
    </collision>
  </link>
  <joint
    name="FL_thigh_joint"
    type="revolute">
    <origin
      xyz="-0.0234 0 0.0226"
      rpy="0 0 0.10521" />
    <parent
      link="FL_hip_link" />
    <child
      link="FL_thigh_link" />
    <axis
      xyz="0 0 1" />
    <limit
      lower="-1.5708"
      upper="1.5708"
      effort="3"
      velocity="8" />
  </joint>
  <link
    name="FL_calf_link">
    <inertial>
      <origin
        xyz="-0.0059573 -0.056415 0.023401"
        rpy="0 0 0" />
      <mass
        value="0.039633" />
      <inertia
        ixx="3.7201E-05"
        ixy="-3.5058E-06"
        ixz="-3.4162E-10"
        iyy="4.3723E-06"
        iyz="-3.0852E-09"
        izz="3.5395E-05" />
    </inertial>
    <visual>
      <origin
        xyz="0 0 0"
        rpy="0 0 0" />
      <geometry>
        <mesh
          filename="package://spot_micro_urdf_v3_rotated_base/meshes/FL_calf_link.STL" />
      </geometry>
      <material
        name="grey">
      </material>
    </visual>
    <collision>
      <origin
        xyz="0 0 0"
        rpy="0 0 0" />
      <geometry>
        <mesh
          filename="package://spot_micro_urdf_v3_rotated_base/meshes/FL_calf_link.STL" />
      </geometry>
    </collision>
  </link>
  <joint
    name="FL_calf_joint"
    type="revolute">
    <origin
      xyz="-0.012392 -0.11735 0"
      rpy="0 0 0" />
    <parent
      link="FL_thigh_link" />
    <child
      link="FL_calf_link" />
    <axis
      xyz="0 0 1" />
    <limit
      lower="-1.5708"
      upper="1.5708"
      effort="3"
      velocity="8" />
  </joint>
  <link
    name="RL_hip_link">
    <inertial>
      <origin
        xyz="0.022101 -0.011251 0.0030217"
        rpy="0 0 0" />
      <mass
        value="0.10229" />
      <inertia
        ixx="2.3388E-05"
        ixy="-3.7973E-08"
        ixz="-4.5621E-13"
        iyy="1.6266E-05"
        iyz="-3.6502E-07"
        izz="2.8445E-05" />
    </inertial>
    <visual>
      <origin
        xyz="0 0 0"
        rpy="0 0 0" />
      <geometry>
        <mesh
          filename="package://spot_micro_urdf_v3_rotated_base/meshes/RL_hip_link.STL" />
      </geometry>
      <material
        name="grey">
      </material>
    </visual>
    <collision>
      <origin
        xyz="0 0 0"
        rpy="0 0 0" />
      <geometry>
        <mesh
          filename="package://spot_micro_urdf_v3_rotated_base/meshes/RL_hip_link.STL" />
      </geometry>
    </collision>
  </link>
  <joint
    name="RL_hip_joint"
    type="revolute">
    <origin
      xyz="-0.07825 0.039001 0.010875"
      rpy="1.5708 0 -3.1416" />
    <parent
      link="base_link" />
    <child
      link="RL_hip_link" />
    <axis
      xyz="-1 0 0" />
    <limit
      lower="-0.1745"
      upper="1.5708"
      effort="3"
      velocity="8" />
  </joint>
  <link
    name="RL_thigh_link">
    <inertial>
      <origin
        xyz="-0.0061957 -0.058673 0.023449"
        rpy="0 0 0" />
      <mass
        value="0.20833" />
      <inertia
        ixx="6.5328E-05"
        ixy="-2.5965E-06"
        ixz="7.6159E-09"
        iyy="4.1013E-05"
        iyz="7.2121E-08"
        izz="5.5965E-05" />
    </inertial>
    <visual>
      <origin
        xyz="0 0 0"
        rpy="0 0 0" />
      <geometry>
        <mesh
          filename="package://spot_micro_urdf_v3_rotated_base/meshes/RL_thigh_link.STL" />
      </geometry>
      <material
        name="blue">
      </material>
    </visual>
    <collision>
      <origin
        xyz="0 0 0"
        rpy="0 0 0" />
      <geometry>
        <mesh
          filename="package://spot_micro_urdf_v3_rotated_base/meshes/RL_thigh_link.STL" />
      </geometry>
    </collision>
  </link>
  <joint
    name="RL_thigh_joint"
    type="revolute">
    <origin
      xyz="0.02175 0 0.0226"
      rpy="0 0 0.10521" />
    <parent
      link="RL_hip_link" />
    <child
      link="RL_thigh_link" />
    <axis
      xyz="0 0 1" />
    <limit
      lower="-1.5708"
      upper="1.5708"
      effort="3"
      velocity="8" />
  </joint>
  <link
    name="RL_calf_link">
    <inertial>
      <origin
        xyz="-0.0059573 -0.056415 0.023401"
        rpy="0 0 0" />
      <mass
        value="0.039633" />
      <inertia
        ixx="3.7201E-05"
        ixy="-3.5058E-06"
        ixz="-3.4162E-10"
        iyy="4.3723E-06"
        iyz="-3.0852E-09"
        izz="3.5395E-05" />
    </inertial>
    <visual>
      <origin
        xyz="0 0 0"
        rpy="0 0 0" />
      <geometry>
        <mesh
          filename="package://spot_micro_urdf_v3_rotated_base/meshes/RL_calf_link.STL" />
      </geometry>
      <material
        name="grey">
      </material>
    </visual>
    <collision>
      <origin
        xyz="0 0 0"
        rpy="0 0 0" />
      <geometry>
        <mesh
          filename="package://spot_micro_urdf_v3_rotated_base/meshes/RL_calf_link.STL" />
      </geometry>
    </collision>
  </link>
  <joint
    name="RL_calf_joint"
    type="revolute">
    <origin
      xyz="-0.012392 -0.11735 0"
      rpy="0 0 0" />
    <parent
      link="RL_thigh_link" />
    <child
      link="RL_calf_link" />
    <axis
      xyz="0 0 1" />
    <limit
      lower="-1.5708"
      upper="1.5708"
      effort="3"
      velocity="8" />
  </joint>
  <link
    name="RR_hip_link">
    <inertial>
      <origin
        xyz="-0.022101 -0.011263 0.0029782"
        rpy="0 0 0" />
      <mass
        value="0.10229" />
      <inertia
        ixx="2.3388E-05"
        ixy="3.7964E-08"
        ixz="1.4601E-10"
        iyy="1.6269E-05"
        iyz="-4.12E-07"
        izz="2.8442E-05" />
    </inertial>
    <visual>
      <origin
        xyz="0 0 0"
        rpy="0 0 0" />
      <geometry>
        <mesh
          filename="package://spot_micro_urdf_v3_rotated_base/meshes/RR_hip_link.STL" />
      </geometry>
      <material
        name="grey">
      </material>
    </visual>
    <collision>
      <origin
        xyz="0 0 0"
        rpy="0 0 0" />
      <geometry>
        <mesh
          filename="package://spot_micro_urdf_v3_rotated_base/meshes/RR_hip_link.STL" />
      </geometry>
    </collision>
  </link>
  <joint
    name="RR_hip_joint"
    type="revolute">
    <origin
      xyz="-0.07825 -0.03901 0.010875"
      rpy="1.5669 0 0" />
    <parent
      link="base_link" />
    <child
      link="RR_hip_link" />
    <axis
      xyz="1 0 0" />
    <limit
      lower="-1.5708"
      upper="0.1745"
      effort="3"
      velocity="8" />
  </joint>
  <link
    name="RR_thigh_link">
    <inertial>
      <origin
        xyz="9.8993E-10 -0.05909 0.023473"
        rpy="0 0 0" />
      <mass
        value="0.20833" />
      <inertia
        ixx="6.5602E-05"
        ixy="3.9386E-13"
        ixz="-2.0136E-14"
        iyy="4.0739E-05"
        iyz="1.3777E-08"
        izz="5.5965E-05" />
    </inertial>
    <visual>
      <origin
        xyz="0 0 0"
        rpy="0 0 0" />
      <geometry>
        <mesh
          filename="package://spot_micro_urdf_v3_rotated_base/meshes/RR_thigh_link.STL" />
      </geometry>
      <material
        name="blue">
      </material>
    </visual>
    <collision>
      <origin
        xyz="0 0 0"
        rpy="0 0 0" />
      <geometry>
        <mesh
          filename="package://spot_micro_urdf_v3_rotated_base/meshes/RR_thigh_link.STL" />
      </geometry>
    </collision>
  </link>
  <joint
    name="RR_thigh_joint"
    type="revolute">
    <origin
      xyz="-0.02175 -8.6996E-05 0.022548"
      rpy="0 0 0" />
    <parent
      link="RR_hip_link" />
    <child
      link="RR_thigh_link" />
    <axis
      xyz="0 0.0038582 -0.99999" />
    <limit
      lower="-1.5708"
      upper="1.5708"
      effort="3"
      velocity="8" />
  </joint>
  <link
    name="RR_calf_link">
    <inertial>
      <origin
        xyz="-0.0059573 -0.056415 -0.02395"
        rpy="0 0 0" />
      <mass
        value="0.039633" />
      <inertia
        ixx="3.7201E-05"
        ixy="-3.5058E-06"
        ixz="-3.4162E-10"
        iyy="4.3723E-06"
        iyz="-3.0852E-09"
        izz="3.5395E-05" />
    </inertial>
    <visual>
      <origin
        xyz="0 0 0"
        rpy="0 0 0" />
      <geometry>
        <mesh
          filename="package://spot_micro_urdf_v3_rotated_base/meshes/RR_calf_link.STL" />
      </geometry>
      <material
        name="grey">
      </material>
    </visual>
    <collision>
      <origin
        xyz="0 0 0"
        rpy="0 0 0" />
      <geometry>
        <mesh
          filename="package://spot_micro_urdf_v3_rotated_base/meshes/RR_calf_link.STL" />
      </geometry>
    </collision>
  </link>
  <joint
    name="RR_calf_joint"
    type="revolute">
    <origin
      xyz="0 -0.118 -0.00045526"
      rpy="3.1378 -0.00040516 3.0364" />
    <parent
      link="RR_thigh_link" />
    <child
      link="RR_calf_link" />
    <axis
      xyz="0 0 1" />
    <limit
      lower="-1.5708"
      upper="1.5708"
      effort="3"
      velocity="8" />
  </joint>
  <link
    name="FR_hip_link">
    <inertial>
      <origin
        xyz="0.023049 -0.011263 0.0029782"
        rpy="0 0 0" />
      <mass
        value="0.10229" />
      <inertia
        ixx="2.3388E-05"
        ixy="3.7964E-08"
        ixz="1.4601E-10"
        iyy="1.6269E-05"
        iyz="-4.12E-07"
        izz="2.8442E-05" />
    </inertial>
    <visual>
      <origin
        xyz="0 0 0"
        rpy="0 0 0" />
      <geometry>
        <mesh
          filename="package://spot_micro_urdf_v3_rotated_base/meshes/FR_hip_link.STL" />
      </geometry>
      <material
        name="grey">
      </material>
    </visual>
    <collision>
      <origin
        xyz="0 0 0"
        rpy="0 0 0" />
      <geometry>
        <mesh
          filename="package://spot_micro_urdf_v3_rotated_base/meshes/FR_hip_link.STL" />
      </geometry>
    </collision>
  </link>
  <joint
    name="FR_hip_joint"
    type="revolute">
    <origin
      xyz="0.0766 -0.039021 0.010875"
      rpy="1.5669 0 0" />
    <parent
      link="base_link" />
    <child
      link="FR_hip_link" />
    <axis
      xyz="1 0 0" />
    <limit
      lower="-1.5708"
      upper="0.1745"
      effort="3"
      velocity="8" />
  </joint>
  <link
    name="FR_thigh_link">
    <inertial>
      <origin
        xyz="9.8993E-10 -0.05909 0.023473"
        rpy="0 0 0" />
      <mass
        value="0.20833" />
      <inertia
        ixx="6.5602E-05"
        ixy="3.9386E-13"
        ixz="-2.0136E-14"
        iyy="4.0739E-05"
        iyz="1.3777E-08"
        izz="5.5965E-05" />
    </inertial>
    <visual>
      <origin
        xyz="0 0 0"
        rpy="0 0 0" />
      <geometry>
        <mesh
          filename="package://spot_micro_urdf_v3_rotated_base/meshes/FR_thigh_link.STL" />
      </geometry>
      <material
        name="blue">
      </material>
    </visual>
    <collision>
      <origin
        xyz="0 0 0"
        rpy="0 0 0" />
      <geometry>
        <mesh
          filename="package://spot_micro_urdf_v3_rotated_base/meshes/FR_thigh_link.STL" />
      </geometry>
    </collision>
  </link>
  <joint
    name="FR_thigh_joint"
    type="revolute">
    <origin
      xyz="0.0234 -8.6996E-05 0.022548"
      rpy="0 0 0" />
    <parent
      link="FR_hip_link" />
    <child
      link="FR_thigh_link" />
    <axis
      xyz="0 0.0038582 -0.99999" />
    <limit
      lower="-1.5708"
      upper="1.5708"
      effort="3"
      velocity="8" />
  </joint>
  <link
    name="FR_calf_link">
    <inertial>
      <origin
        xyz="-0.0059573 -0.056415 -0.02395"
        rpy="0 0 0" />
      <mass
        value="0.039633" />
      <inertia
        ixx="3.7201E-05"
        ixy="-3.5058E-06"
        ixz="-3.4162E-10"
        iyy="4.3723E-06"
        iyz="-3.0852E-09"
        izz="3.5395E-05" />
    </inertial>
    <visual>
      <origin
        xyz="0 0 0"
        rpy="0 0 0" />
      <geometry>
        <mesh
          filename="package://spot_micro_urdf_v3_rotated_base/meshes/FR_calf_link.STL" />
      </geometry>
      <material
        name="grey">
      </material>
    </visual>
    <collision>
      <origin
        xyz="0 0 0"
        rpy="0 0 0" />
      <geometry>
        <mesh
          filename="package://spot_micro_urdf_v3_rotated_base/meshes/FR_calf_link.STL" />
      </geometry>
    </collision>
  </link>
  <joint
    name="FR_calf_joint"
    type="revolute">
    <origin
      xyz="0 -0.118 -0.00045526"
      rpy="3.1378 -0.00040516 3.0364" />
    <parent
      link="FR_thigh_link" />
    <child
      link="FR_calf_link" />
    <axis
      xyz="0 0 1" />
    <limit
      lower="-1.5708"
      upper="1.5708"
      effort="3"
      velocity="8" />
  </joint>
</robot>
